Workbook

Sheet BASETRANSPORTE
A1: Data | B1: Frota | C1: Modelo | D1: Toneladas | E1: Total Viagens | F1: Toneladas por viagem | G1: Distancia Média | H1: EMPRESA | I1: Mês
A2: 46129 | B2: 2066 | C2: 115-MB AXOR 3340 6X4 | D2: 461.14 | E2: 8 | F2: 57.643 | G2: 1 | H2: =IF(B2="","",VLOOKUP(B2,[1]BASEEMPRESA!$A$2:$AAA$11936,2)) -> NDB HOLDING AGRICOLA LTDA - MATRIZ | I2: =TEXT(A2,"mmm") -> abr
A3: 46129 | B3: 2067 | C3: 115-MB AXOR 3340 6X4 | D3: 481.08 | E3: 8 | F3: 60.135 | G3: 1 | H3: =IF(B3="","",VLOOKUP(B3,[1]BASEEMPRESA!$A$2:$AAA$11936,2)) -> NDB HOLDING AGRICOLA LTDA - MATRIZ | I3: =TEXT(A3,"mmm") -> abr
A4: 46129 | B4: 2107 | C4: 115-MB AXOR 3340 6X4 | D4: 413.18 | E4: 7 | F4: 59.026 | G4: 1.301 | H4: =IF(B4="","",VLOOKUP(B4,[1]BASEEMPRESA!$A$2:$AAA$11936,2)) -> NDB HOLDING AGRICOLA LTDA - MATRIZ | I4: =TEXT(A4,"mmm") -> abr
A5: 46129 | B5: 7004 | C5: 850-TER MB AXOR 3344 6X4 | D5: 128.72 | E5: 2 | F5: 64.36 | G5: 47.596 | H5: =IF(B5="","",VLOOKUP(B5,[1]BASEEMPRESA!$A$2:$AAA$11936,2)) -> EMERSON LUIS MORO | I5: =TEXT(A5,"mmm") -> abr
A6: 46129 | B6: 7007 | C6: 852-TER MB AXOR 3340 S 6X4 | D6: 136.34 | E6: 2 | F6: 68.17 | G6: 48.081 | H6: =IF(B6="","",VLOOKUP(B6,[1]BASEEMPRESA!$A$2:$AAA$11936,2)) -> MVS TRANSPORTE LTDA | I6: =TEXT(A6,"mmm") -> abr
A7: 46129 | B7: 7008 | C7: 850-TER MB AXOR 3344 6X4 | D7: 130.64 | E7: 2 | F7: 65.32 | G7: 24.553 | H7: =IF(B7="","",VLOOKUP(B7,[1]BASEEMPRESA!$A$2:$AAA$11936,2)) -> E L DE OLIVEIRA JUNIOR EDIMAR TRANSPORTES | I7: =TEXT(A7,"mmm") -> abr
A8: 46129 | B8: 7010 | C8: 850-TER MB AXOR 3344 6X4 | D8: 58.54 | E8: 1 | F8: 58.54 | G8: 41.75 | H8: =IF(B8="","",VLOOKUP(B8,[1]BASEEMPRESA!$A$2:$AAA$11936,2)) -> BAYER LOGISTICA E TRANSPORTES LTDA | I8: =TEXT(A8,"mmm") -> abr
A9: 46129 | B9: 7017 | C9: 850-TER MB AXOR 3344 6X4 | D9: 64.8 | E9: 1 | F9: 64.8 | G9: 58 | H9: =IF(B9="","",VLOOKUP(B9,[1]BASEEMPRESA!$A$2:$AAA$11936,2)) -> BAYER LOGISTICA E TRANSPORTES LTDA | I9: =TEXT(A9,"mmm") -> abr
A10: 46129 | B10: 7018 | C10: 850-TER MB AXOR 3344 6X4 | D10: 65.64 | E10: 1 | F10: 65.64 | G10: 3 | H10: =IF(B10="","",VLOOKUP(B10,[1]BASEEMPRESA!$A$2:$AAA$11936,2)) -> SC MANUTENCOES LTDA | I10: =TEXT(A10,"mmm") -> abr
A11: 46129 | B11: 7021 | C11: 850-TER MB AXOR 3344 6X4 | D11: 120.62 | E11: 2 | F11: 60.31 | G11: 15 | H11: =IF(B11="","",VLOOKUP(B11,[1]BASEEMPRESA!$A$2:$AAA$11936,2)) -> NEIA TRANSPORTES LTDA | I11: =TEXT(A11,"mmm") -> abr
A12: 46129 | B12: 7032 | C12: 850-TER MB AXOR 3344 6X4 | D12: 114.92 | E12: 2 | F12: 57.46 | G12: 49.807 | H12: =IF(B12="","",VLOOKUP(B12,[1]BASEEMPRESA!$A$2:$AAA$11936,2)) -> REGINA M. DOS S. SILVA CARGAS | I12: =TEXT(A12,"mmm") -> abr
A13: 46129 | B13: 7033 | C13: 850-TER MB AXOR 3344 6X4 | D13: 124.96 | E13: 2 | F13: 62.48 | G13: 23.422 | H13: =IF(B13="","",VLOOKUP(B13,[1]BASEEMPRESA!$A$2:$AAA$11936,2)) -> E L DE OLIVEIRA JUNIOR EDIMAR TRANSPORTES | I13: =TEXT(A13,"mmm") -> abr
... A875: 46143 | B875: 7355 | C875: 850-TER MB AXOR 3344 6X4 | D875: 185.3 | E875: 3 | F875: 61.767 | G875: 22.73 | H875: =IF(B875="","",VLOOKUP(B875,[1]BASEEMPRESA!$A$2:$AAA$11936,2)) -> WESLEI M DOS SANTOS | I875: =TEXT(A875,"mmm") -> mai
A876: 46143 | B876: 7364 | C876: 850-TER MB AXOR 3344 6X4 | D876: =244.88-9.18 -> 235.7 | E876: 4 | F876: 61.22 | G876: 10 | H876: =IF(B876="","",VLOOKUP(B876,[1]BASEEMPRESA!$A$2:$AAA$11936,2)) -> TRANSPORTADORA GLOBAL LOGISTICA LTDA | I876: =TEXT(A876,"mmm") -> mai
A877: 46143 | B877: 7367 | C877: 850-TER MB AXOR 3344 6X4 | D877: 56.92 | E877: 1 | F877: 56.92 | G877: 83 | H877: =IF(B877="","",VLOOKUP(B877,[1]BASEEMPRESA!$A$2:$AAA$11936,2)) -> JOSE HELIO SILVA SANTOS | I877: =TEXT(A877,"mmm") -> mai
A878: 46143 | B878: 7370 | C878: 850-TER MB AXOR 3344 6X4 | D878: 177.12 | E878: 3 | F878: 59.04 | G878: 37.833 | H878: =IF(B878="","",VLOOKUP(B878,[1]BASEEMPRESA!$A$2:$AAA$11936,2)) -> JOSE HELIO SILVA SANTOS | I878: =TEXT(A878,"mmm") -> mai
A879: 46143 | B879: 7373 | C879: 855-TER SCANIA G 440 A 6X4 | D879: 118.14 | E879: 2 | F879: 59.07 | G879: 12.417 | H879: =IF(B879="","",VLOOKUP(B879,[1]BASEEMPRESA!$A$2:$AAA$11936,2)) -> BARBOSA TRANSPORTES E LOGISTICA LTDA | I879: =TEXT(A879,"mmm") -> mai
A880: 46143 | B880: 7381 | C880: 938-TER VOLVO/FM12 420 6X4T | D880: 191.8 | E880: 3 | F880: 63.933 | G880: 13.37 | H880: =IF(B880="","",VLOOKUP(B880,[1]BASEEMPRESA!$A$2:$AAA$11936,2)) -> TRANSPORTE FUMACINHA LTDA | I880: =TEXT(A880,"mmm") -> mai
A881: 46144 | B881: 2066 | C881: 115-MB AXOR 3340 6X4 | D881: 467.44 | E881: 8 | F881: 58.43 | G881: 1 | H881: =IF(B881="","",VLOOKUP(B881,[1]BASEEMPRESA!$A$2:$AAA$11936,2)) -> NDB HOLDING AGRICOLA LTDA - MATRIZ | I881: =TEXT(A881,"mmm") -> mai
A882: 46144 | B882: 2067 | C882: 115-MB AXOR 3340 6X4 | D882: 413.06 | E882: 7 | F882: 59.009 | G882: 1 | H882: =IF(B882="","",VLOOKUP(B882,[1]BASEEMPRESA!$A$2:$AAA$11936,2)) -> NDB HOLDING AGRICOLA LTDA - MATRIZ | I882: =TEXT(A882,"mmm") -> mai
A883: 46144 | B883: 2107 | C883: 115-MB AXOR 3340 6X4 | D883: 294.82 | E883: 5 | F883: 58.964 | G883: 2.94 | H883: =IF(B883="","",VLOOKUP(B883,[1]BASEEMPRESA!$A$2:$AAA$11936,2)) -> NDB HOLDING AGRICOLA LTDA - MATRIZ | I883: =TEXT(A883,"mmm") -> mai
A884: 46144 | B884: 2108 | C884: 115-MB AXOR 3340 6X4 | D884: 412.86 | E884: 7 | F884: 58.98 | G884: 2.365 | H884: =IF(B884="","",VLOOKUP(B884,[1]BASEEMPRESA!$A$2:$AAA$11936,2)) -> NDB HOLDING AGRICOLA LTDA - MATRIZ | I884: =TEXT(A884,"mmm") -> mai
A885: 46144 | B885: 7004 | C885: 850-TER MB AXOR 3344 6X4 | D885: 119.22 | E885: 2 | F885: 59.61 | G885: 68.194 | H885: =IF(B885="","",VLOOKUP(B885,[1]BASEEMPRESA!$A$2:$AAA$11936,2)) -> EMERSON LUIS MORO | I885: =TEXT(A885,"mmm") -> mai
A886: 46144 | B886: 7005 | C886: 850-TER MB AXOR 3344 6X4 | D886: 118.68 | E886: 2 | F886: 59.34 | G886: 83 | H886: =IF(B886="","",VLOOKUP(B886,[1]BASEEMPRESA!$A$2:$AAA$11936,2)) -> RENE PINA DE ALMEIDA | I886: =TEXT(A886,"mmm") -> mai
A887: 46144 | B887: 7006 | C887: 852-TER MB AXOR 3340 S 6X4 | D887: 194.2 | E887: 3 | F887: 64.733 | G887: 36.91 | H887: =IF(B887="","",VLOOKUP(B887,[1]BASEEMPRESA!$A$2:$AAA$11936,2)) -> INAMARQUE SOUZA MACHADO | I887: =TEXT(A887,"mmm") -> mai
A888: 46144 | B888: 7007 | C888: 852-TER MB AXOR 3340 S 6X4 | D888: 181.38 | E888: 3 | F888: 60.46 | G888: 29.002 | H888: =IF(B888="","",VLOOKUP(B888,[1]BASEEMPRESA!$A$2:$AAA$11936,2)) -> MVS TRANSPORTE LTDA | I888: =TEXT(A888,"mmm") -> mai
... A5967: 46219 | B5967: 7404 | C5967: 850-TER MB AXOR 3344 6X4 | D5967: 123.42 | E5967: 2 | F5967: 61.71 | G5967: 66 | H5967: =IF(B5967="","",VLOOKUP(B5967,[1]BASEEMPRESA!$A$2:$AAA$11936,2)) -> RSL TRANSPORTES LTDA | I5967: =TEXT(A5967,"mmm") -> jul

Sheet DISPONIBILIDADE
A1: Equipamento | B1: Corporativo | C1: Unidade | D1: Tipo Equipamento | E1: Frente | F1: Operador | G1: Disponibilidade Mecânica
A2: 3051 | B2: ALCON | C2: Colhedora | D2: Frente 1 | E2: CASE 9900 | F2: -1 - * não definido * | G2: 1
A3: 3052 | B3: ALCON | C3: Colhedora | D3: Frente 1 | E3: CASE 9900 | F3: 702299 - RAIMUNDO FAGNO CASSQUI DE JESUS | G3: 1
A4: 3052 | B4: ALCON | C4: Colhedora | D4: Frente 1 | E4: CASE 9900 | F4: 9999 - * não definido * | G4: 1
A5: 3053 | B5: ALCON | C5: Colhedora | D5: Frente 1 | E5: CASE 9900 | F5: 9999 - * não definido * | G5: 1
A6: 3019 | B6: ALCON | C6: Colhedora | D6: Frente 2 | E6: John Deere CH 570 | F6: -1 - * não definido * | G6: 1
A7: 3020 | B7: ALCON | C7: Colhedora | D7: Frente 2 | E7: John Deere CH 570 | F7: 5253 - TALLYS JHONE COSVOSK PEDREIRA | G7: 1
A8: 3020 | B8: ALCON | C8: Colhedora | D8: Frente 2 | E8: John Deere CH 570 | F8: 9999 - * não definido * | G8: 1
A9: 3021 | B9: ALCON | C9: Colhedora | D9: Frente 2 | E9: John Deere CH 570 | F9: -1 - * não definido * | G9: 1
A10: 3021 | B10: ALCON | C10: Colhedora | D10: Frente 2 | E10: John Deere CH 570 | F10: 702410 - FLAVIO CLAUDIANO DE SOUZA | G10: 1
A11: 3021 | B11: ALCON | C11: Colhedora | D11: Frente 2 | E11: John Deere CH 570 | F11: 9999 - * não definido * | G11: 1
A12: 3022 | B12: ALCON | C12: Colhedora | D12: Frente 2 | E12: John Deere CH 570 | F12: -1 - * não definido * | G12: 1
A13: 3023 | B13: ALCON | C13: Colhedora | D13: Frente 3 | E13: John Deere CH 570 | F13: -1 - * não definido * | G13: 1
... A1000: 4139 | B1000: ALCON | C1000: TRANSBORDO | D1000: FRENTE 8 | E1000: John Deere 7210 | F1000: 3360 - ISRAEL JESUS DA SILVA | G1000: 0

Sheet Mes
B1: MÊS | C1: INICIO | D1: FIM | E1: DIAS | F1: MOAGEM
A2: 4 | B2: Abril | C2: 45748 | D2: 45777 | E2: =D2-C2+1 -> 30 | F2: 30
A3: 5 | B3: Maio | C3: 45778 | D3: 45808 | E3: =D3-C3+1 -> 31 | F3: 31
A4: 6 | B4: Junho | C4: 45809 | D4: 45838 | E4: =D4-C4+1 -> 30 | F4: 30
A5: 7 | B5: Julho | C5: 45839 | D5: 45869 | E5: =D5-C5+1 -> 31 | F5: 31
A6: 8 | B6: Agosto | C6: 45870 | D6: 45900 | E6: =D6-C6+1 -> 31 | F6: 31
A7: 9 | B7: Setembro | C7: 45901 | D7: 45930 | E7: =D7-C7+1 -> 30 | F7: 24
A8: 10 | B8: Outubro | C8: 45931 | D8: 45961 | E8: =D8-C8+1 -> 31 | F8: 26
A9: 11 | B9: Novembro | C9: 45962 | D9: 45991 | E9: =D9-C9+1 -> 30 | F9: 27
A10: 12 | B10: Dezembro | C10: 45992 | D10: 46022 | E10: =D10-C10+1 -> 31 | F10: 26 | I10: =TODAY() -> 46224
A11: 1 | B11: Janeiro | C11: 46023 | D11: 46053 | E11: =D11-C11+1 -> 31 | F11: =I11-C11+1 -> 202 | I11: =TODAY() -> 46224
A12: 2 | B12: Fevereiro | C12: 46054 | D12: 46081 | E12: =D12-C12+1 -> 28 | F12: =I12-C12+1 -> 171 | I12: =TODAY() -> 46224
A13: 3 | B13: Março | C13: 46082 | D13: 46112 | E13: =D13-C13+1 -> 31 | F13: =I13-C13+1 -> 143 | I13: =TODAY() -> 46224
B14: TOTAL | C14: 45748 | D14: 46101 | E14: =D14-C14+1 -> 354 | F14: =TODAY()-C14 -> 476 | I14: =TODAY() -> 46224

Sheet Plan4
A3: Rótulos de Linha | B3: Soma de Toneladas
A4: abr | B4: 144240.25
A5: mai | B5: 326148.25
A6: jun | B6: 307979.99
A7: (vazio)
A8: Total geral | B8: 778368.49

Sheet BASECOLHEDORA
A1: Data | B1: Frota | C1: Modelo | D1: COD_PROPRIETARIO | E1: PROPRIETARIO | F1: Toneladas | G1: Total Cargas | H1: Média Carga | I1: FRENTE
A2: 46129 | B2: 3019 | C2: 100-JOHN DEERE CH570 ESTEIRA | D2: 4533 | E2: NDB HOLDING AGRICOLA LTDA - MATRIZ | F2: 358.12 | G2: 22 | H2: 16.28 | I2: =IF(B2="","",VLOOKUP(B2,[1]BASEDIESEL!$A$2:$AAA$11770,6)) -> FRENTE-02
A3: 46129 | B3: 3020 | C3: 100-JOHN DEERE CH570 ESTEIRA | D3: 4533 | E3: NDB HOLDING AGRICOLA LTDA - MATRIZ | F3: 273.79 | G3: 18 | H3: 15.21 | I3: =IF(B3="","",VLOOKUP(B3,[1]BASEDIESEL!$A$2:$AAA$11770,6)) -> FRENTE-02
A4: 46129 | B4: 3021 | C4: 100-JOHN DEERE CH570 ESTEIRA | D4: 4533 | E4: NDB HOLDING AGRICOLA LTDA - MATRIZ | F4: 342.405 | G4: 21 | H4: 16.31 | I4: =IF(B4="","",VLOOKUP(B4,[1]BASEDIESEL!$A$2:$AAA$11770,6)) -> FRENTE-02
A5: 46129 | B5: 3022 | C5: 100-JOHN DEERE CH570 ESTEIRA | D5: 4533 | E5: NDB HOLDING AGRICOLA LTDA - MATRIZ | F5: 318.945 | G5: 19 | H5: 16.79 | I5: =IF(B5="","",VLOOKUP(B5,[1]BASEDIESEL!$A$2:$AAA$11770,6)) -> FRENTE-02
A6: 46129 | B6: 3023 | C6: 100-JOHN DEERE CH570 ESTEIRA | D6: 4533 | E6: NDB HOLDING AGRICOLA LTDA - MATRIZ | F6: 394.958 | G6: 18 | H6: 21.94 | I6: =IF(B6="","",VLOOKUP(B6,[1]BASEDIESEL!$A$2:$AAA$11770,6)) -> FRENTE-03
A7: 46129 | B7: 3024 | C7: 100-JOHN DEERE CH570 ESTEIRA | D7: 4533 | E7: NDB HOLDING AGRICOLA LTDA - MATRIZ | F7: 206.498 | G7: 11 | H7: 18.77 | I7: =IF(B7="","",VLOOKUP(B7,[1]BASEDIESEL!$A$2:$AAA$11770,6)) -> FRENTE-03
A8: 46129 | B8: 3025 | C8: 100-JOHN DEERE CH570 ESTEIRA | D8: 4533 | E8: NDB HOLDING AGRICOLA LTDA - MATRIZ | F8: 156.295 | G8: 8 | H8: 19.54 | I8: =IF(B8="","",VLOOKUP(B8,[1]BASEDIESEL!$A$2:$AAA$11770,6)) -> FRENTE-03
A9: 46129 | B9: 3026 | C9: 100-JOHN DEERE CH570 ESTEIRA | D9: 4533 | E9: NDB HOLDING AGRICOLA LTDA - MATRIZ | F9: 44.069 | G9: 3 | H9: 14.69 | I9: =IF(B9="","",VLOOKUP(B9,[1]BASEDIESEL!$A$2:$AAA$11770,6)) -> FRENTE-03
A10: 46129 | B10: 3027 | C10: 101-JOHN DEERE CH670 ESTEIRA | D10: 4533 | E10: NDB HOLDING AGRICOLA LTDA - MATRIZ | F10: 234.582 | G10: 12 | H10: 19.55 | I10: =IF(B10="","",VLOOKUP(B10,[1]BASEDIESEL!$A$2:$AAA$11770,6)) -> FRENTE-04
A11: 46129 | B11: 3028 | C11: 101-JOHN DEERE CH670 ESTEIRA | D11: 4533 | E11: NDB HOLDING AGRICOLA LTDA - MATRIZ | F11: 369.636 | G11: 14 | H11: 26.4 | I11: =IF(B11="","",VLOOKUP(B11,[1]BASEDIESEL!$A$2:$AAA$11770,6)) -> FRENTE-06
A12: 46129 | B12: 3029 | C12: 101-JOHN DEERE CH670 ESTEIRA | D12: 4533 | E12: NDB HOLDING AGRICOLA LTDA - MATRIZ | F12: 281.76 | G12: 10 | H12: 28.18 | I12: =IF(B12="","",VLOOKUP(B12,[1]BASEDIESEL!$A$2:$AAA$11770,6)) -> FRENTE-07
A13: 46129 | B13: 3030 | C13: 101-JOHN DEERE CH670 ESTEIRA | D13: 4533 | E13: NDB HOLDING AGRICOLA LTDA - MATRIZ | F13: 167.978 | G13: 9 | H13: 18.66 | I13: =IF(B13="","",VLOOKUP(B13,[1]BASEDIESEL!$A$2:$AAA$11770,6)) -> FRENTE-07
... A1726: 46189 | B1726: 3045 | C1726: 100-JOHN DEERE CH570 ESTEIRA | D1726: 4533 | E1726: NDB HOLDING AGRICOLA LTDA - MATRIZ | F1726: 440.002 | G1726: 27 | H1726: 16.3 | I1726: =IF(B1726="","",VLOOKUP(B1726,[1]BASEDIESEL!$A$2:$AAA$11770,6)) -> FRENTE-07
A1727: 46189 | B1727: 3033 | C1727: 101-JOHN DEERE CH670 ESTEIRA | D1727: 4533 | E1727: NDB HOLDING AGRICOLA LTDA - MATRIZ | F1727: =226.268+69.82 -> 296.088 | G1727: 16 | H1727: 14.14 | I1727: =IF(B1727="","",VLOOKUP(B1727,[1]BASEDIESEL!$A$2:$AAA$11770,6)) -> FRENTE-07
A1728: 46190 | B1728: 3051 | C1728: 201-CASE A9900 ESTEIRA | D1728: 1 | E1728: ALCON CIA DE ALCOOL CONCEICAO DA BARRA | F1728: 782.63 | G1728: 49 | H1728: 15.97 | I1728: =IF(B1728="","",VLOOKUP(B1728,[1]BASEDIESEL!$A$2:$AAA$11770,6)) -> FRENTE-01
A1729: 46190 | B1729: 3052 | C1729: 201-CASE A9900 ESTEIRA | D1729: 1 | E1729: ALCON CIA DE ALCOOL CONCEICAO DA BARRA | F1729: 797.97 | G1729: 48 | H1729: 16.62 | I1729: =IF(B1729="","",VLOOKUP(B1729,[1]BASEDIESEL!$A$2:$AAA$11770,6)) -> FRENTE-01
A1730: 46190 | B1730: 3053 | C1730: 201-CASE A9900 ESTEIRA | D1730: 1 | E1730: ALCON CIA DE ALCOOL CONCEICAO DA BARRA | F1730: 782.895 | G1730: 48 | H1730: 16.31 | I1730: =IF(B1730="","",VLOOKUP(B1730,[1]BASEDIESEL!$A$2:$AAA$11770,6)) -> FRENTE-01
A1731: 46190 | B1731: 3054 | C1731: 201-CASE A9900 ESTEIRA | D1731: 1 | E1731: ALCON CIA DE ALCOOL CONCEICAO DA BARRA | F1731: 632.365 | G1731: 39 | H1731: 16.21 | I1731: =IF(B1731="","",VLOOKUP(B1731,[1]BASEDIESEL!$A$2:$AAA$11770,6)) -> FRENTE-01
A1732: 46190 | B1732: 3019 | C1732: 100-JOHN DEERE CH570 ESTEIRA | D1732: 4533 | E1732: NDB HOLDING AGRICOLA LTDA - MATRIZ | F1732: 651.1 | G1732: 37 | H1732: 17.6 | I1732: =IF(B1732="","",VLOOKUP(B1732,[1]BASEDIESEL!$A$2:$AAA$11770,6)) -> FRENTE-02
A1733: 46190 | B1733: 3020 | C1733: 100-JOHN DEERE CH570 ESTEIRA | D1733: 4533 | E1733: NDB HOLDING AGRICOLA LTDA - MATRIZ | F1733: 741.74 | G1733: 42 | H1733: 17.66 | I1733: =IF(B1733="","",VLOOKUP(B1733,[1]BASEDIESEL!$A$2:$AAA$11770,6)) -> FRENTE-02
A1734: 46190 | B1734: 3021 | C1734: 100-JOHN DEERE CH570 ESTEIRA | D1734: 4533 | E1734: NDB HOLDING AGRICOLA LTDA - MATRIZ | F1734: 483.245 | G1734: 30 | H1734: 16.11 | I1734: =IF(B1734="","",VLOOKUP(B1734,[1]BASEDIESEL!$A$2:$AAA$11770,6)) -> FRENTE-02
A1735: 46190 | B1735: 3022 | C1735: 100-JOHN DEERE CH570 ESTEIRA | D1735: 4533 | E1735: NDB HOLDING AGRICOLA LTDA - MATRIZ | F1735: 445.295 | G1735: 29 | H1735: 15.36 | I1735: =IF(B1735="","",VLOOKUP(B1735,[1]BASEDIESEL!$A$2:$AAA$11770,6)) -> FRENTE-02
A1736: 46190 | B1736: 3023 | C1736: 100-JOHN DEERE CH570 ESTEIRA | D1736: 4533 | E1736: NDB HOLDING AGRICOLA LTDA - MATRIZ | F1736: 338.118 | G1736: 19 | H1736: 17.8 | I1736: =IF(B1736="","",VLOOKUP(B1736,[1]BASEDIESEL!$A$2:$AAA$11770,6)) -> FRENTE-03
A1737: 46190 | B1737: 3024 | C1737: 100-JOHN DEERE CH570 ESTEIRA | D1737: 4533 | E1737: NDB HOLDING AGRICOLA LTDA - MATRIZ | F1737: 390.242 | G1737: 24 | H1737: 16.26 | I1737: =IF(B1737="","",VLOOKUP(B1737,[1]BASEDIESEL!$A$2:$AAA$11770,6)) -> FRENTE-03
A1738: 46190 | B1738: 3025 | C1738: 100-JOHN DEERE CH570 ESTEIRA | D1738: 4533 | E1738: NDB HOLDING AGRICOLA LTDA - MATRIZ | F1738: 258.478 | G1738: 15 | H1738: 17.23 | I1738: =IF(B1738="","",VLOOKUP(B1738,[1]BASEDIESEL!$A$2:$AAA$11770,6)) -> FRENTE-03
A1739: 46190 | B1739: 3026 | C1739: 100-JOHN DEERE CH570 ESTEIRA | D1739: 4533 | E1739: NDB HOLDING AGRICOLA LTDA - MATRIZ | F1739: 196.342 | G1739: 14 | H1739: 14.02 | I1739: =IF(B1739="","",VLOOKUP(B1739,[1]BASEDIESEL!$A$2:$AAA$11770,6)) -> FRENTE-03
... A2531: 46219 | B2531: 3054 | C2531: 201-CASE A9900 ESTEIRA | D2531: 1 | E2531: ALCON CIA DE ALCOOL CONCEICAO DA BARRA | F2531: 694.22 | G2531: 40 | H2531: 17.36 | I2531: =IF(B2531="","",VLOOKUP(B2531,[1]BASEDIESEL!$A$2:$AAA$11770,6)) -> FRENTE-01

Sheet Plan3
A3: Rótulos de Linha
A4: (vazio)
A5: 4019
A6: 4024
A7: 4025
A8: 4027
A9: 4029
A10: 4030
A11: 4032
A12: 4034
A13: 4035
A14: 4036
A15: 4082
A16: 4112
... A68: 4061
A69: Total geral

Sheet Plan1
A3: Rótulos de Linha | B3: Soma de Toneladas
A4: 4019 | B4: 3417.803
A5: 4020 | B5: 1209.7
A6: 4021 | B6: 2884.286
A7: 4022 | B7: 952.541
A8: 4024 | B8: 9925.656
A9: 4025 | B9: 4318.701
A10: 4027 | B10: 10441.177
A11: 4029 | B11: 10309.05
A12: 4030 | B12: 7077.234
A13: 4032 | B13: 6576.584
A14: 4033 | B14: 3692.96
A15: 4034 | B15: 7270.868
... A67: 4163 | B67: 13770.517
A68: (vazio)
A69: Total geral | B69: 658705.11

Sheet BASETRANSBORDO
A1: Data | B1: Frota | C1: Modelo | D1: Toneladas | E1: Total Cargas | F1: Média Carga | G1: Frente | H1: Mês
A2: 46129 | B2: 4019 | C2: 236-TRATOR JOHN DEERE 6180 J | D2: 129.836 | E2: 7 | F2: 18.548 | G2: =IF(B2="","",VLOOKUP(B2,[1]BASEDIESEL!$A$2:$AAA$11928,6)) -> FRENTE-07 | H2: =TEXT(A2,"mmm") -> abr
A3: 46129 | B3: 4024 | C3: 236-TRATOR JOHN DEERE 6180 J | D3: 129.857 | E3: 8 | F3: 16.232 | G3: =IF(B3="","",VLOOKUP(B3,[1]BASEDIESEL!$A$2:$AAA$11928,6)) -> FRENTE-07 | H3: =TEXT(A3,"mmm") -> abr
A4: 46129 | B4: 4025 | C4: 236-TRATOR JOHN DEERE 6180 J | D4: 182.545 | E4: 11 | F4: 16.595 | G4: =IF(B4="","",VLOOKUP(B4,[1]BASEDIESEL!$A$2:$AAA$11928,6)) -> FRENTE-07 | H4: =TEXT(A4,"mmm") -> abr
A5: 46129 | B5: 4027 | C5: 236-TRATOR JOHN DEERE 6180 J | D5: 123.358 | E5: 9 | F5: 13.706 | G5: =IF(B5="","",VLOOKUP(B5,[1]BASEDIESEL!$A$2:$AAA$11928,6)) -> FRENTE-07 | H5: =TEXT(A5,"mmm") -> abr
A6: 46129 | B6: 4029 | C6: 236-TRATOR JOHN DEERE 6180 J | D6: 196.84 | E6: 11 | F6: 17.895 | G6: =IF(B6="","",VLOOKUP(B6,[1]BASEDIESEL!$A$2:$AAA$11928,6)) -> FRENTE-07 | H6: =TEXT(A6,"mmm") -> abr
A7: 46129 | B7: 4030 | C7: 285-TRATOR JOHN DEERE 7185 J | D7: 89.409 | E7: 6 | F7: 14.902 | G7: =IF(B7="","",VLOOKUP(B7,[1]BASEDIESEL!$A$2:$AAA$11928,6)) -> FRENTE-06 | H7: =TEXT(A7,"mmm") -> abr
A8: 46129 | B8: 4032 | C8: 238-TRATOR JOHN DEERE 7195 J | D8: 70.226 | E8: 4 | F8: 17.557 | G8: =IF(B8="","",VLOOKUP(B8,[1]BASEDIESEL!$A$2:$AAA$11928,6)) -> FRENTE-06 | H8: =TEXT(A8,"mmm") -> abr
A9: 46129 | B9: 4034 | C9: 238-TRATOR JOHN DEERE 7195 J | D9: 13.409 | E9: 2 | F9: 6.705 | G9: =IF(B9="","",VLOOKUP(B9,[1]BASEDIESEL!$A$2:$AAA$11928,6)) -> FRENTE-06 | H9: =TEXT(A9,"mmm") -> abr
A10: 46129 | B10: 4035 | C10: 238-TRATOR JOHN DEERE 7195 J | D10: 64.924 | E10: 3 | F10: 21.641 | G10: =IF(B10="","",VLOOKUP(B10,[1]BASEDIESEL!$A$2:$AAA$11928,6)) -> FRENTE-06 | H10: =TEXT(A10,"mmm") -> abr
A11: 46129 | B11: 4036 | C11: 238-TRATOR JOHN DEERE 7195 J | D11: 61.751 | E11: 3 | F11: 20.584 | G11: =IF(B11="","",VLOOKUP(B11,[1]BASEDIESEL!$A$2:$AAA$11928,6)) -> FRENTE-06 | H11: =TEXT(A11,"mmm") -> abr
A12: 46129 | B12: 4036 | C12: 238-TRATOR JOHN DEERE 7195 J | D12: 19.11 | E12: 1 | F12: 19.11 | G12: =IF(B12="","",VLOOKUP(B12,[1]BASEDIESEL!$A$2:$AAA$11928,6)) -> FRENTE-06 | H12: =TEXT(A12,"mmm") -> abr
A13: 46129 | B13: 4112 | C13: 258-TRATOR JOHN DEERE 7210 J | D13: 82.465 | E13: 5 | F13: 16.493 | G13: =IF(B13="","",VLOOKUP(B13,[1]BASEDIESEL!$A$2:$AAA$11928,6)) -> FRENTE-01 | H13: =TEXT(A13,"mmm") -> abr
... A3197: 46189 | B3197: 4155 | C3197: 265-TRATOR JOHN DEERE 7225 J | D3197: 146.879 | E3197: 8 | F3197: 18.36 | G3197: =IF(B3197="","",VLOOKUP(B3197,[1]BASEDIESEL!$A$2:$AAA$11928,6)) -> FRENTE-04 | H3197: =TEXT(A3197,"mmm") -> jun
A3198: 46189 | B3198: 4156 | C3198: 258-TRATOR JOHN DEERE 7210 J | D3198: =246.475+69.82 -> 316.295 | E3198: 17 | F3198: 14.499 | G3198: =IF(B3198="","",VLOOKUP(B3198,[1]BASEDIESEL!$A$2:$AAA$11928,6)) -> FRENTE-02 | H3198: =TEXT(A3198,"mmm") -> jun
A3199: 46189 | B3199: 4157 | C3199: 258-TRATOR JOHN DEERE 7210 J | D3199: 144.198 | E3199: 9 | F3199: 16.022 | G3199: =IF(B3199="","",VLOOKUP(B3199,[1]BASEDIESEL!$A$2:$AAA$11928,6)) -> FRENTE-06 | H3199: =TEXT(A3199,"mmm") -> jun
A3200: 46189 | B3200: 4158 | C3200: 258-TRATOR JOHN DEERE 7210 J | D3200: 199.672 | E3200: 12 | F3200: 16.639 | G3200: =IF(B3200="","",VLOOKUP(B3200,[1]BASEDIESEL!$A$2:$AAA$11928,6)) -> FRENTE-03 | H3200: =TEXT(A3200,"mmm") -> jun
A3201: 46189 | B3201: 4159 | C3201: 258-TRATOR JOHN DEERE 7210 J | D3201: 230.605 | E3201: 16 | F3201: 14.413 | G3201: =IF(B3201="","",VLOOKUP(B3201,[1]BASEDIESEL!$A$2:$AAA$11928,6)) -> FRENTE-02 | H3201: =TEXT(A3201,"mmm") -> jun
A3202: 46189 | B3202: 4160 | C3202: 258-TRATOR JOHN DEERE 7210 J | D3202: 293.09 | E3202: 20 | F3202: 14.655 | G3202: =IF(B3202="","",VLOOKUP(B3202,[1]BASEDIESEL!$A$2:$AAA$11928,6)) -> FRENTE-01 | H3202: =TEXT(A3202,"mmm") -> jun
A3203: 46189 | B3203: 4161 | C3203: 258-TRATOR JOHN DEERE 7210 J | D3203: 139.884 | E3203: 11 | F3203: 12.717 | G3203: =IF(B3203="","",VLOOKUP(B3203,[1]BASEDIESEL!$A$2:$AAA$11928,6)) -> FRENTE-07 | H3203: =TEXT(A3203,"mmm") -> jun
A3204: 46189 | B3204: 4162 | C3204: 258-TRATOR JOHN DEERE 7210 J | D3204: 283.42 | E3204: 20 | F3204: 14.171 | G3204: =IF(B3204="","",VLOOKUP(B3204,[1]BASEDIESEL!$A$2:$AAA$11928,6)) -> FRENTE-02 | H3204: =TEXT(A3204,"mmm") -> jun
A3205: 46189 | B3205: 4163 | C3205: 258-TRATOR JOHN DEERE 7210 J | D3205: 234.125 | E3205: 16 | F3205: 14.633 | G3205: =IF(B3205="","",VLOOKUP(B3205,[1]BASEDIESEL!$A$2:$AAA$11928,6)) -> FRENTE-02 | H3205: =TEXT(A3205,"mmm") -> jun
A3206: 46190 | B3206: 4024 | C3206: 236-TRATOR JOHN DEERE 6180 J | D3206: 205.67 | E3206: 15 | F3206: 13.711 | G3206: =IF(B3206="","",VLOOKUP(B3206,[1]BASEDIESEL!$A$2:$AAA$11928,6)) -> FRENTE-07 | H3206: =TEXT(A3206,"mmm") -> jun
A3207: 46190 | B3207: 4025 | C3207: 236-TRATOR JOHN DEERE 6180 J | D3207: 100.414 | E3207: 7 | F3207: 14.345 | G3207: =IF(B3207="","",VLOOKUP(B3207,[1]BASEDIESEL!$A$2:$AAA$11928,6)) -> FRENTE-07 | H3207: =TEXT(A3207,"mmm") -> jun
A3208: 46190 | B3208: 4027 | C3208: 236-TRATOR JOHN DEERE 6180 J | D3208: 185.109 | E3208: 12 | F3208: 15.426 | G3208: =IF(B3208="","",VLOOKUP(B3208,[1]BASEDIESEL!$A$2:$AAA$11928,6)) -> FRENTE-07 | H3208: =TEXT(A3208,"mmm") -> jun
A3209: 46190 | B3209: 4029 | C3209: 236-TRATOR JOHN DEERE 6180 J | D3209: 211.864 | E3209: 18 | F3209: 11.77 | G3209: =IF(B3209="","",VLOOKUP(B3209,[1]BASEDIESEL!$A$2:$AAA$11928,6)) -> FRENTE-07 | H3209: =TEXT(A3209,"mmm") -> jun
A3210: 46190 | B3210: 4030 | C3210: 285-TRATOR JOHN DEERE 7185 J | D3210: 29.048 | E3210: 2 | F3210: 14.524 | G3210: =IF(B3210="","",VLOOKUP(B3210,[1]BASEDIESEL!$A$2:$AAA$11928,6)) -> FRENTE-06 | H3210: =TEXT(A3210,"mmm") -> jun
... A4797: 46219 | B4797: 4163 | C4797: 258-TRATOR JOHN DEERE 7210 J | D4797: 274.87 | E4797: 20 | F4797: 13.744 | G4797: =IF(B4797="","",VLOOKUP(B4797,[1]BASEDIESEL!$A$2:$AAA$11928,6)) -> FRENTE-02 | H4797: =TEXT(A4797,"mmm") -> jul

Sheet Plan5
A1: Data | B1: 46043
A3: Rótulos de Linha
A4: 1094
A5: 493
A6: 1322
A7: 655
A8: 1522
A9: 523
A10: 1090
A11: 663
A12: 1300
A13: 205
A14: 1426
... A16: Total geral

Sheet BASEDIESEL
A1: Equip. | B1: Ton. Cana | C1: Lt | D1: Lt/ton | E1: Safra | F1: Frente | G1: DATA | H1: TIPO
A2: 3019 | B2: 41487.109 | C2: 48450.7 | D2: 1.1678 | E2: 2026/2027 | F2: =IF(A2="","",VLOOKUP(A2,[1]Base!$A$2:$K$11917,3,FALSE)) -> FRENTE-02 | G2: =NOW()-1 -> 46223.013 | H2: =IF(A2="","",VLOOKUP(A2,[1]Base!$A$2:$K$11917,5,FALSE)) -> COLHEDORA
A3: 3020 | B3: 30824.956 | C3: 44040.4 | D3: 1.4287 | E3: 2026/2027 | F3: =IF(A3="","",VLOOKUP(A3,[1]Base!$A$2:$K$11917,3,FALSE)) -> FRENTE-02 | G3: =NOW()-1 -> 46223.013 | H3: =IF(A3="","",VLOOKUP(A3,[1]Base!$A$2:$K$11917,5,FALSE)) -> COLHEDORA
A4: 3021 | B4: 38752.456 | C4: 44337.1 | D4: 1.1441 | E4: 2026/2027 | F4: =IF(A4="","",VLOOKUP(A4,[1]Base!$A$2:$K$11917,3,FALSE)) -> FRENTE-02 | G4: =NOW()-1 -> 46223.013 | H4: =IF(A4="","",VLOOKUP(A4,[1]Base!$A$2:$K$11917,5,FALSE)) -> COLHEDORA
A5: 3022 | B5: 35871.179 | C5: 47639.6 | D5: 1.3281 | E5: 2026/2027 | F5: =IF(A5="","",VLOOKUP(A5,[1]Base!$A$2:$K$11917,3,FALSE)) -> FRENTE-02 | G5: =NOW()-1 -> 46223.013 | H5: =IF(A5="","",VLOOKUP(A5,[1]Base!$A$2:$K$11917,5,FALSE)) -> COLHEDORA
A6: 3023 | B6: 36617.298 | C6: 39407.2 | D6: 1.0762 | E6: 2026/2027 | F6: =IF(A6="","",VLOOKUP(A6,[1]Base!$A$2:$K$11917,3,FALSE)) -> FRENTE-03 | G6: =NOW()-1 -> 46223.013 | H6: =IF(A6="","",VLOOKUP(A6,[1]Base!$A$2:$K$11917,5,FALSE)) -> COLHEDORA
A7: 3024 | B7: 32581.587 | C7: 40399.4 | D7: 1.2399 | E7: 2026/2027 | F7: =IF(A7="","",VLOOKUP(A7,[1]Base!$A$2:$K$11917,3,FALSE)) -> FRENTE-03 | G7: =NOW()-1 -> 46223.013 | H7: =IF(A7="","",VLOOKUP(A7,[1]Base!$A$2:$K$11917,5,FALSE)) -> COLHEDORA
A8: 3025 | B8: 29795.378 | C8: 37030.3 | D8: 1.2428 | E8: 2026/2027 | F8: =IF(A8="","",VLOOKUP(A8,[1]Base!$A$2:$K$11917,3,FALSE)) -> FRENTE-03 | G8: =NOW()-1 -> 46223.013 | H8: =IF(A8="","",VLOOKUP(A8,[1]Base!$A$2:$K$11917,5,FALSE)) -> COLHEDORA
A9: 3026 | B9: 32250.098 | C9: 34842.3 | D9: 1.0804 | E9: 2026/2027 | F9: =IF(A9="","",VLOOKUP(A9,[1]Base!$A$2:$K$11917,3,FALSE)) -> FRENTE-03 | G9: =NOW()-1 -> 46223.013 | H9: =IF(A9="","",VLOOKUP(A9,[1]Base!$A$2:$K$11917,5,FALSE)) -> COLHEDORA
A10: 3027 | B10: 11434.49 | C10: 16816.2 | D10: 1.4707 | E10: 2026/2027 | F10: =IF(A10="","",VLOOKUP(A10,[1]Base!$A$2:$K$11917,3,FALSE)) -> FRENTE-04 | G10: =NOW()-1 -> 46223.013 | H10: =IF(A10="","",VLOOKUP(A10,[1]Base!$A$2:$K$11917,5,FALSE)) -> COLHEDORA
A11: 3028 | B11: 21798.564 | C11: 33321.7 | D11: 1.5286 | E11: 2026/2027 | F11: =IF(A11="","",VLOOKUP(A11,[1]Base!$A$2:$K$11917,3,FALSE)) -> FRENTE-06 | G11: =NOW()-1 -> 46223.013 | H11: =IF(A11="","",VLOOKUP(A11,[1]Base!$A$2:$K$11917,5,FALSE)) -> COLHEDORA
A12: 3029 | B12: 3216.274 | C12: 7132 | D12: 2.2175 | E12: 2026/2027 | F12: =IF(A12="","",VLOOKUP(A12,[1]Base!$A$2:$K$11917,3,FALSE)) -> FRENTE-07 | G12: =NOW()-1 -> 46223.013 | H12: =IF(A12="","",VLOOKUP(A12,[1]Base!$A$2:$K$11917,5,FALSE)) -> COLHEDORA
A13: 3030 | B13: 25415.171 | C13: 47445.2 | D13: 1.8668 | E13: 2026/2027 | F13: =IF(A13="","",VLOOKUP(A13,[1]Base!$A$2:$K$11917,3,FALSE)) -> FRENTE-07 | G13: =NOW()-1 -> 46223.013 | H13: =IF(A13="","",VLOOKUP(A13,[1]Base!$A$2:$K$11917,5,FALSE)) -> COLHEDORA
... A94: 4163 | B94: 18384.382 | C94: 9241.9 | D94: 0.5027 | E94: 2026/2027 | F94: =IF(A94="","",VLOOKUP(A94,[1]Base!$A$2:$K$11917,3,FALSE)) -> FRENTE-02 | G94: =NOW()-1 -> 46223.013 | H94: =IF(A94="","",VLOOKUP(A94,[1]Base!$A$2:$K$11917,5,FALSE)) -> TRANSBORDO

Sheet BASE
A1: Equip. | B1: Ton. Cana | C1: LTS | D1: LTS/TON | E1: DATA | F1: TIPO
A2: 3019 | B2: 26778.509 | C2: 30795.4 | D2: 1.15 | E2: =MAX(BASECOLHEDORA!A:A) -> 46219 | F2: =IF(A2="","",VLOOKUP(A2,DISPONIBILIDADE!$B$2:$AAA$11936,3)) -> #N/A
A3: 3020 | B3: 21438.31 | C3: 30768.1 | D3: 1.4352 | E3: =MAX(BASECOLHEDORA!A:A) -> 46219
A4: 3021 | B4: 25809.86 | C4: 28795.1 | D4: 1.1157 | E4: =MAX(BASECOLHEDORA!A:A) -> 46219
A5: 3022 | B5: 23868.281 | C5: 30081 | D5: 1.2603 | E5: =MAX(BASECOLHEDORA!A:A) -> 46219
A6: 3023 | B6: 25770.332 | C6: 27678.1 | D6: 1.074 | E6: =MAX(BASECOLHEDORA!A:A) -> 46219
A7: 3024 | B7: 21315.966 | C7: 27457.2 | D7: 1.2881 | E7: =MAX(BASECOLHEDORA!A:A) -> 46219
A8: 3025 | B8: 19244.375 | C8: 24494.1 | D8: 1.2728 | E8: =MAX(BASECOLHEDORA!A:A) -> 46219
A9: 3026 | B9: 20542.221 | C9: 23149.7 | D9: 1.1269 | E9: =MAX(BASECOLHEDORA!A:A) -> 46219
A10: 3027 | B10: 11434.49 | C10: 17275.7 | D10: 1.5108 | E10: =MAX(BASECOLHEDORA!A:A) -> 46219
A11: 3028 | B11: 12526.117 | C11: 20014 | D11: 1.5978 | E11: =MAX(BASECOLHEDORA!A:A) -> 46219
A12: 3029 | B12: 3216.274 | C12: 7638 | D12: 2.3748 | E12: =MAX(BASECOLHEDORA!A:A) -> 46219
A13: 3030 | B13: 18771.123 | C13: 35191 | D13: 1.8747 | E13: =MAX(BASECOLHEDORA!A:A) -> 46219
A14: 3031 | B14: 14506.028 | C14: 25957.4 | D14: 1.7894 | E14: =MAX(BASECOLHEDORA!A:A) -> 46219
... A34: 3054 | B34: 25765.736 | C34: 27403.3 | D34: 1.0636 | E34: =MAX(BASECOLHEDORA!A:A) -> 46219
A35: 4019 | B35: 3417.803 | C35: 2407.4 | D35: 0.7044 | E35: =MAX(BASETRANSBORDO!A:A) -> 46219
A36: 4020 | B36: 1209.7 | C36: 1076.7 | D36: 0.89 | E36: =MAX(BASETRANSBORDO!A:A) -> 46219
A37: 4021 | B37: 2884.286 | C37: 2667.6 | D37: 0.9249 | E37: =MAX(BASETRANSBORDO!A:A) -> 46219
A38: 4022 | B38: 952.541 | C38: 1459 | D38: 1.5317 | E38: =MAX(BASETRANSBORDO!A:A) -> 46219
A39: 4024 | B39: 8989.406 | C39: 5486.8 | D39: 0.6104 | E39: =MAX(BASETRANSBORDO!A:A) -> 46219
A40: 4025 | B40: 3871.021 | C40: 2960.3 | D40: 0.7647 | E40: =MAX(BASETRANSBORDO!A:A) -> 46219
A41: 4027 | B41: 9779.281 | C41: 6058.1 | D41: 0.6195 | E41: =MAX(BASETRANSBORDO!A:A) -> 46219
A42: 4029 | B42: 9524.793 | C42: 5286.4 | D42: 0.555 | E42: =MAX(BASETRANSBORDO!A:A) -> 46219
A43: 4030 | B43: 6524.116 | C43: 4486.2 | D43: 0.6876 | E43: =MAX(BASETRANSBORDO!A:A) -> 46219
A44: 4032 | B44: 6033.462 | C44: 4778.6 | D44: 0.792 | E44: =MAX(BASETRANSBORDO!A:A) -> 46219
A45: 4033 | B45: 3382.771 | C45: 3746.9 | D45: 1.1076 | E45: =MAX(BASETRANSBORDO!A:A) -> 46219
A46: 4034 | B46: 6760.315 | C46: 4662.2 | D46: 0.6896 | E46: =MAX(BASETRANSBORDO!A:A) -> 46219
... A98: 4163 | B98: 12560.657 | C98: 6214.9 | D98: 0.4948 | E98: =MAX(BASETRANSBORDO!A:A) -> 46219

Sheet BASEEMPRESA
A1: FROTA | B1: EMPRESA
A2: 2059 | B2: NDB HOLDING AGRICOLA LTDA - MATRIZ
A3: 2066 | B3: NDB HOLDING AGRICOLA LTDA - MATRIZ
A4: 2067 | B4: NDB HOLDING AGRICOLA LTDA - MATRIZ
A5: 2107 | B5: NDB HOLDING AGRICOLA LTDA - MATRIZ
A6: 2108 | B6: NDB HOLDING AGRICOLA LTDA - MATRIZ
A7: 2109 | B7: NDB HOLDING AGRICOLA LTDA - MATRIZ
A8: 7004 | B8: EMERSON LUIS MORO
A9: 7005 | B9: RENE PINA DE ALMEIDA
A10: 7006 | B10: INAMARQUE SOUZA MACHADO
A11: 7007 | B11: MVS TRANSPORTE LTDA
A12: 7008 | B12: E L DE OLIVEIRA JUNIOR EDIMAR TRANSPORTES
A13: 7010 | B13: BAYER LOGISTICA E TRANSPORTES LTDA
... A76: 7398 | B76: RSL TRANSPORTES LTDA

Sheet COLHEDORA
A1: COLEDORA | D1: TRANSBORDO | G1: TRANSPORTE
A3: Rótulos de Linha | B3: Soma de Toneladas | D3: Rótulos de Linha | E3: Soma de Toneladas | G3: Rótulos de Linha | H3: Soma de Toneladas
A4: 46129 | B4: 5390.42 | D4: 46129 | E4: 5390.42 | G4: 46129 | H4: 5390.42 | J4: OK
A5: 46130 | B5: 9768.38 | D5: 46130 | E5: 9768.38 | G5: 46130 | H5: 9768.38 | J5: OK
A6: 46131 | B6: 10659.2 | D6: 46131 | E6: 10659.2 | G6: 46131 | H6: 10659.2 | J6: OK
A7: 46132 | B7: 5399.48 | D7: 46132 | E7: 5399.48 | G7: 46132 | H7: 5399.48 | J7: OK
A8: 46133 | B8: 12063.21 | D8: 46133 | E8: 12063.21 | G8: 46133 | H8: 12063.21 | J8: OK
A9: 46134 | B9: 12460.82 | D9: 46134 | E9: 12460.82 | G9: 46134 | H9: 12460.82 | J9: OK
A10: 46135 | B10: 9951.12 | D10: 46135 | E10: 9951.12 | G10: 46135 | H10: 9951.12 | J10: OK
A11: 46136 | B11: 11746.9 | D11: 46136 | E11: 11746.9 | G11: 46136 | H11: 11746.9 | J11: OK
A12: 46137 | B12: 12768.92 | D12: 46137 | E12: 12768.92 | G12: 46137 | H12: 12768.92 | J12: OK
A13: 46138 | B13: 13010.42 | D13: 46138 | E13: 13010.42 | G13: 46138 | H13: 13010.42 | J13: OK
A14: 46139 | B14: 12940.53 | D14: 46139 | E14: 12940.53 | G14: 46139 | H14: 12940.53 | J14: OK
A15: 46140 | B15: 4541.7 | D15: 46140 | E15: 4541.7 | G15: 46140 | H15: 4541.7
A16: 46141 | B16: 11615.75 | D16: 46141 | E16: 11615.75 | G16: 46141 | H16: 11615.75 | J16: OK
A17: 46142 | B17: 11923.4 | D17: 46142 | E17: 11923.4 | G17: 46142 | H17: 11923.4 | J17: OK
A18: 46143 | B18: 12355.18 | D18: 46143 | E18: 12355.18 | G18: 46143 | H18: 12355.18
A19: 46144 | B19: 11403.71 | D19: 46144 | E19: 11403.71 | G19: 46144 | H19: 11403.71
A20: 46145 | B20: 9185.74 | D20: 46145 | E20: 9185.74 | G20: 46145 | H20: 9185.74 | J20: OK
A21: 46146 | B21: 6169.95 | D21: 46146 | E21: 6169.95 | G21: 46146 | H21: 6169.95 | J21: OK
A22: 46147 | B22: 3465.06 | D22: 46147 | E22: 3465.06 | G22: 46147 | H22: 3465.06 | J22: OK
A23: 46148 | B23: 10716.81 | D23: 46148 | E23: 10716.81 | G23: 46148 | H23: 10716.81 | J23: OK
A24: 46149 | B24: 9680.67 | D24: 46149 | E24: 9680.67 | G24: 46149 | H24: 9680.67
A25: 46150 | B25: 6526.26 | D25: 46150 | E25: 6526.26 | G25: 46150 | H25: 6526.26 | J25: OK
A26: 46151 | B26: 10996.58 | D26: 46151 | E26: 10996.58 | G26: 46151 | H26: 10996.58 | J26: OK
A27: 46152 | B27: 9220.8 | D27: 46152 | E27: 9220.8 | G27: 46152 | H27: 9220.8
A28: 46153 | B28: 11909.68 | D28: 46153 | E28: 11909.68 | G28: 46153 | H28: 11909.68 | J28: OK
A29: 46154 | B29: 11880.04 | D29: 46154 | E29: 11880.04 | G29: 46154 | H29: 11880.04 | J29: OK
A30: 46155 | B30: 12274.17 | D30: 46155 | E30: 12274.17 | G30: 46155 | H30: 12274.17
A31: 46156 | B31: 12027.94 | D31: 46156 | E31: 12027.94 | G31: 46156 | H31: 12027.94
A32: 46157 | B32: 13722.8 | D32: 46157 | E32: 13722.8 | G32: 46157 | H32: 13722.8
A33: 46158 | B33: 13270.68 | D33: 46158 | E33: 13270.68 | G33: 46158 | H33: 13270.68
A34: 46159 | B34: 12446.5 | D34: 46159 | E34: 12446.5 | G34: 46159 | H34: 12446.5
A35: 46160 | B35: 8376.16 | D35: 46160 | E35: 8376.16 | G35: 46160 | H35: 8376.16
A36: 46161 | B36: 8295.64 | D36: 46161 | E36: 8295.64 | G36: 46161 | H36: 8295.64
A37: 46162 | B37: 12629.84 | D37: 46162 | E37: 12629.84 | G37: 46162 | H37: 12629.84
A38: 46163 | B38: 11930.04 | D38: 46163 | E38: 11930.04 | G38: 46163 | H38: 11930.04
A39: 46164 | B39: 7164.88 | D39: 46164 | E39: 7164.88 | G39: 46164 | H39: 7164.88
A40: 46165 | B40: 0 | D40: 46165 | E40: 0 | G40: 46165 | H40: 0 | J40: OK
A41: 46166 | B41: 10070.8 | D41: 46166 | E41: 10070.8 | G41: 46166 | H41: 10070.8 | J41: OK
...

Sheet Plan8
A2: COLEDORA | D2: TRANSBORDO | G2: TRANSPORTE
A3: 46129 | B3: 5390.42 | D3: 46129 | E3: 5390.42 | G3: 46129 | H3: 5390.42 | J3: =B3-E3-H3 -> -5390.42 | K3: =J3+B3 -> 0 | L3: =J3+E3 -> 0 | M3: =J3+H3 -> 0
A4: 46130 | B4: 9768.38 | D4: 46130 | E4: 9768.38 | G4: 46130 | H4: 9768.38 | J4: =B4-E4-H4 -> -9768.38 | K4: =J4+B4 -> 0 | L4: =J4+E4 -> 0 | M4: =J4+H4 -> 0
A5: 46131 | B5: 10659.2 | D5: 46131 | E5: 10659.2 | G5: 46131 | H5: 10659.2 | J5: =B5-E5-H5 -> -10659.2 | K5: =J5+B5 -> 0 | L5: =J5+E5 -> 0 | M5: =J5+H5 -> 0
A6: 46132 | B6: 5399.48 | D6: 46132 | E6: 5399.48 | G6: 46132 | H6: 5399.48 | J6: =B6-E6-H6 -> -5399.48 | K6: =J6+B6 -> 0 | L6: =J6+E6 -> 0 | M6: =J6+H6 -> 0
A7: 46133 | B7: 12063.21 | D7: 46133 | E7: 12063.21 | G7: 46133 | H7: 12063.21 | J7: =B7-E7-H7 -> -12063.21 | K7: =J7+B7 -> 0 | L7: =J7+E7 -> 0 | M7: =J7+H7 -> 0
A8: 46134 | B8: 12460.82 | D8: 46134 | E8: 12460.82 | G8: 46134 | H8: 12460.82 | J8: =B8-E8-H8 -> -12460.82 | K8: =J8+B8 -> 0 | L8: =J8+E8 -> 0 | M8: =J8+H8 -> 0
A9: 46135 | B9: 9951.12 | D9: 46135 | E9: 9951.12 | G9: 46135 | H9: 9951.12 | J9: =B9-E9-H9 -> -9951.12 | K9: =J9+B9 -> 0 | L9: =J9+E9 -> 0 | M9: =J9+H9 -> 0
A10: 46136 | B10: 11746.9 | D10: 46136 | E10: 11746.9 | G10: 46136 | H10: 11746.9 | J10: =B10-E10-H10 -> -11746.9 | K10: =J10+B10 -> 0 | L10: =J10+E10 -> 0 | M10: =J10+H10 -> 0
A11: 46137 | B11: 12768.92 | D11: 46137 | E11: 12768.92 | G11: 46137 | H11: 12768.92 | J11: =B11-E11-H11 -> -12768.92 | K11: =J11+B11 -> 0 | L11: =J11+E11 -> 0 | M11: =J11+H11 -> 0
A12: 46138 | B12: 13010.42 | D12: 46138 | E12: 13010.42 | G12: 46138 | H12: 13010.42 | J12: =B12-E12-H12 -> -13010.42 | K12: =J12+B12 -> 0 | L12: =J12+E12 -> 0 | M12: =J12+H12 -> 0
A13: 46139 | B13: 12940.53 | D13: 46139 | E13: 12940.53 | G13: 46139 | H13: 12940.53 | J13: =B13-E13-H13 -> -12940.53 | K13: =J13+B13 -> 0 | L13: =J13+E13 -> 0 | M13: =J13+H13 -> 0
A14: 46140 | B14: 4541.7 | D14: 46140 | E14: 4541.7 | G14: 46140 | H14: 4541.7 | J14: =B14-E14-H14 -> -4541.7 | K14: =J14+B14 -> 0 | L14: =J14+E14 -> 0 | M14: =J14+H14 -> 0
... A64: 46190 | B64: 11671.48 | D64: 46190 | E64: 11671.48 | G64: 46190 | H64: 11671.48 | J64: =B64-E64-H64 -> -11671.48 | K64: =J64+B64 -> 0 | L64: =J64+E64 -> 0 | M64: =J64+H64 -> 0
K65: =SUM(K3:K64) -> 1.4551915e-11 | L65: =SUM(L3:L64) -> 0 | M65: =SUM(M3:M64) -> 0

Sheet COLHEITA
A1: Projeto | B1: Safra | C1: Setor | D1: Cod. fazenda | E1: Fazenda | F1: Gleba | G1: Talhão | H1: Estágio | I1: Status Talhão | J1: Finalidade | K1: Data Ultima Entrega | L1: Total Área O.S. | M1: Área Estimada | N1: Área Colhida | O1: % Área Colhida | P1: Prod. Est. | Q1: Prod. Real | R1: Saldo Produção | S1: TCH Est. | T1: TCH Real | U1: % Variação TCH | V1: cidade
A2: 2026/2027 | B2: 2026/2027 | C2: ACIONISTA | D2: 167 | E2: FAZ. SAYONARA - PROJETO 16 | F2: 01-PROXIMO | G2: 016 | H2: 1C 12M | I2: Colheita Encerrada | J2: MOAGEM | K2: 04/05/2026 | L2: 3.07 | M2: 3.07 | N2: 3.07 | O2: 100 | P2: 337.7 | Q2: 462.191 | R2: -124.491 | S2: 110 | T2: 150.55 | U2: 36.86 | V2: Conceição da Barra
A3: 2026/2027 | B3: 2026/2027 | C3: ACIONISTA | D3: 167 | E3: FAZ. SAYONARA - PROJETO 16 | F3: 01-PROXIMO | G3: 017 | H3: 1C 12M | I3: Colheita Encerrada | J3: MOAGEM | K3: 04/05/2026 | L3: 4.03 | M3: 4.03 | N3: 4.03 | O3: 100 | P3: 443.3 | Q3: 606.706 | R3: -163.406 | S3: 110 | T3: 150.55 | U3: 36.86 | V3: Braço do Rio
A4: 2026/2027 | B4: 2026/2027 | C4: ACIONISTA | D4: 167 | E4: FAZ. SAYONARA - PROJETO 16 | F4: 01-PROXIMO | G4: 018 | H4: 1C 12M | I4: Colheita Encerrada | J4: MOAGEM | K4: 04/05/2026 | L4: 4.47 | M4: 4.47 | N4: 4.47 | O4: 100 | P4: 491.7 | Q4: 672.968 | R4: -181.268 | S4: 110 | T4: 150.55 | U4: 36.87 | V4: Pedro Canario
A5: 2026/2027 | B5: 2026/2027 | C5: ACIONISTA | D5: 167 | E5: FAZ. SAYONARA - PROJETO 16 | F5: 01-PROXIMO | G5: 019 | H5: 1C 12M | I5: Colheita Encerrada | J5: MOAGEM | K5: 04/05/2026 | L5: 1.31 | M5: 1.31 | N5: 1.31 | O5: 100 | P5: 144.1 | Q5: 197.221 | R5: -53.121 | S5: 110 | T5: 150.55 | U5: 36.86 | V5: Nanuque
A6: 2026/2027 | B6: 2026/2027 | C6: ACIONISTA | D6: 167 | E6: FAZ. SAYONARA - PROJETO 16 | F6: 01-PROXIMO | G6: 020 | H6: 1C 12M | I6: Colheita Encerrada | J6: MOAGEM | K6: 04/05/2026 | L6: 5.24 | M6: 5.24 | N6: 5.24 | O6: 100 | P6: 576.4 | Q6: 788.891 | R6: -212.491 | S6: 110 | T6: 150.55 | U6: 36.87 | V6: São Mateus
A7: 2026/2027 | B7: 2026/2027 | C7: ACIONISTA | D7: 167 | E7: FAZ. SAYONARA - PROJETO 16 | F7: 01-PROXIMO | G7: 021 | H7: 1C 12M | I7: Colheita Encerrada | J7: MOAGEM | K7: 04/05/2026 | L7: 4.48 | M7: 4.48 | N7: 4.48 | O7: 100 | P7: 492.8 | Q7: 674.475 | R7: -181.675 | S7: 110 | T7: 150.55 | U7: 36.87 | V7: Pinheiros
A8: 2026/2027 | B8: 2026/2027 | C8: ACIONISTA | D8: 167 | E8: FAZ. SAYONARA - PROJETO 16 | F8: 01-PROXIMO | G8: 022 | H8: 1C 12M | I8: Colheita Encerrada | J8: MOAGEM | K8: 04/05/2026 | L8: 10.66 | M8: 10.66 | N8: 10.66 | O8: 100 | P8: 1172.6 | Q8: 1604.868 | R8: -432.268 | S8: 110 | T8: 150.55 | U8: 36.86 | V8: Boa Esperaça
A9: 2026/2027 | B9: 2026/2027 | C9: ACIONISTA | D9: 167 | E9: FAZ. SAYONARA - PROJETO 16 | F9: 01-PROXIMO | G9: 023 | H9: 1C 12M | I9: Colheita Encerrada | J9: MOAGEM | K9: 04/05/2026 | L9: 16.4 | M9: 16.4 | N9: 16.4 | O9: 100 | P9: 1804 | Q9: 2469.037 | R9: -665.037 | S9: 110 | T9: 150.55 | U9: 36.86 | V9: Mucuri
A10: 2026/2027 | B10: 2026/2027 | C10: ACIONISTA | D10: 167 | E10: FAZ. SAYONARA - PROJETO 16 | F10: 01-PROXIMO | G10: 024 | H10: 1C 12M | I10: Colheita Encerrada | J10: MOAGEM | K10: 04/05/2026 | L10: 10.32 | M10: 10.32 | N10: 10.32 | O10: 100 | P10: 1135.2 | Q10: 1553.677 | R10: -418.477 | S10: 110 | T10: 150.55 | U10: 36.86 | V10: Motanha
A11: 2026/2027 | B11: 2026/2027 | C11: ACIONISTA | D11: 167 | E11: FAZ. SAYONARA - PROJETO 16 | F11: 01-PROXIMO | G11: 025 | H11: 1C 12M | I11: Colheita Encerrada | J11: MOAGEM | K11: 04/05/2026 | L11: 12.53 | M11: 12.53 | N11: 12.53 | O11: 100 | P11: 1378.3 | Q11: 1886.404 | R11: -508.104 | S11: 110 | T11: 150.55 | U11: 36.86 | V11: Conceição da Barra
A12: 2026/2027 | B12: 2026/2027 | C12: ACIONISTA | D12: 167 | E12: FAZ. SAYONARA - PROJETO 16 | F12: 01-PROXIMO | G12: 026 | H12: 1C 12M | I12: Colheita Encerrada | J12: MOAGEM | K12: 04/05/2026 | L12: 1.89 | M12: 1.89 | N12: 1.89 | O12: 100 | P12: 207.9 | Q12: 284.54 | R12: -76.64 | S12: 110 | T12: 150.55 | U12: 36.86 | V12: Braço do Rio
A13: 2026/2027 | B13: 2026/2027 | C13: ACIONISTA | D13: 167 | E13: FAZ. SAYONARA - PROJETO 16 | F13: 01-PROXIMO | G13: 027 | H13: 1C 12M | I13: Colheita Encerrada | J13: MOAGEM | K13: 04/05/2026 | L13: 10.74 | M13: 10.74 | N13: 10.74 | O13: 100 | P13: 1181.4 | Q13: 1616.969 | R13: -435.569 | S13: 110 | T13: 150.56 | U13: 36.87 | V13: Pedro Canario
... A19: 2026/2027 | B19: 2026/2027 | C19: ACIONISTA | D19: 8664 | E19: FAZ. CORDANTA A_ Nerzy | F19: 30-CORDANTA | G19: 013 | H19: 1C 12M | I19: Colheita Encerrada | J19: MOAGEM | K19: 22/05/2026 | L19: 6.96 | M19: 6.96 | N19: 6.96 | O19: 100 | P19: 835.2 | Q19: 1219.734 | R19: -384.534 | S19: 120 | T19: 175.25 | U19: 46.04 | V19: Motanha
A20: 2026/2027 | B20: 2026/2027 | C20: ACIONISTA | D20: 8664 | E20: FAZ. CORDANTA A_ Nerzy | F20: 30-CORDANTA | G20: 014 | H20: 1C 12M | I20: Colheita Encerrada | J20: MOAGEM | K20: 22/05/2026 | L20: 7.02 | M20: 7.02 | N20: 7.02 | O20: 100 | P20: 842.4 | Q20: 1230.258 | R20: -387.858 | S20: 120 | T20: 175.25 | U20: 46.04
A21: 2026/2027 | B21: 2026/2027 | C21: ACIONISTA | D21: 8664 | E21: FAZ. CORDANTA A_ Nerzy | F21: 30-CORDANTA | G21: 015 | H21: 1C 12M | I21: Colheita Encerrada | J21: MOAGEM | K21: 22/05/2026 | L21: 7.21 | M21: 7.21 | N21: 7.21 | O21: 100 | P21: 865.2 | Q21: 1263.542 | R21: -398.342 | S21: 120 | T21: 175.25 | U21: 46.04
A22: 2026/2027 | B22: 2026/2027 | C22: ACIONISTA | D22: 8664 | E22: FAZ. CORDANTA A_ Nerzy | F22: 30-CORDANTA | G22: 016 | H22: 1C 12M | I22: Colheita Encerrada | J22: MOAGEM | K22: 22/05/2026 | L22: 4.83 | M22: 4.83 | N22: 4.83 | O22: 100 | P22: 579.6 | Q22: 846.507 | R22: -266.907 | S22: 120 | T22: 175.26 | U22: 46.05
A23: 2026/2027 | B23: 2026/2027 | C23: ACIONISTA | D23: 8664 | E23: FAZ. CORDANTA A_ Nerzy | F23: 30-CORDANTA | G23: 017 | H23: 1C 12M | I23: Colheita Encerrada | J23: MOAGEM | K23: 22/05/2026 | L23: 3.6 | M23: 3.6 | N23: 3.6 | O23: 100 | P23: 432 | Q23: 630.885 | R23: -198.885 | S23: 120 | T23: 175.25 | U23: 46.04
A24: 2026/2027 | B24: 2026/2027 | C24: ACIONISTA | D24: 8664 | E24: FAZ. CORDANTA A_ Nerzy | F24: 30-CORDANTA | G24: 018 | H24: 1C 12M | I24: Colheita Encerrada | J24: MOAGEM | K24: 22/05/2026 | L24: 10.13 | M24: 10.13 | N24: 10.13 | O24: 100 | P24: 1215.6 | Q24: 1775.257 | R24: -559.657 | S24: 120 | T24: 175.25 | U24: 46.04
A25: 2026/2027 | B25: 2026/2027 | C25: ACIONISTA | D25: 8664 | E25: FAZ. CORDANTA A_ Nerzy | F25: 30-CORDANTA | G25: 019 | H25: 1C 12M | I25: Colheita Encerrada | J25: MOAGEM | K25: 22/05/2026 | L25: 2.56 | M25: 2.56 | N25: 2.56 | O25: 100 | P25: 307.2 | Q25: 448.636 | R25: -141.436 | S25: 120 | T25: 175.25 | U25: 46.04
A26: 2026/2027 | B26: 2026/2027 | C26: ACIONISTA | D26: 8664 | E26: FAZ. CORDANTA A_ Nerzy | F26: 30-CORDANTA | G26: 020 | H26: 1C 12M | I26: Colheita Encerrada | J26: MOAGEM | K26: 22/05/2026 | L26: 2.85 | M26: 2.85 | N26: 2.85 | O26: 100 | P26: 342 | Q26: 499.447 | R26: -157.447 | S26: 120 | T26: 175.24 | U26: 46.04
A27: 2026/2027 | B27: 2026/2027 | C27: ACIONISTA | D27: 8664 | E27: FAZ. CORDANTA A_ Nerzy | F27: 30-CORDANTA | G27: 021 | H27: 1C 12M | I27: Colheita Encerrada | J27: MOAGEM | K27: 22/05/2026 | L27: 4.26 | M27: 4.26 | N27: 4.26 | O27: 100 | P27: 511.2 | Q27: 746.556 | R27: -235.356 | S27: 120 | T27: 175.25 | U27: 46.04 | V27: Conceição da Barra
A28: 2026/2027 | B28: 2026/2027 | C28: ACIONISTA | D28: 8664 | E28: FAZ. CORDANTA A_ Nerzy | F28: 30-CORDANTA | G28: 022 | H28: 1C 12M | I28: Colheita Encerrada | J28: MOAGEM | K28: 22/05/2026 | L28: 5.39 | M28: 5.39 | N28: 5.39 | O28: 100 | P28: 646.8 | Q28: 944.579 | R28: -297.779 | S28: 120 | T28: 175.25 | U28: 46.04 | V28: Braço do Rio
A29: 2026/2027 | B29: 2026/2027 | C29: ACIONISTA | D29: 8664 | E29: FAZ. CORDANTA A_ Nerzy | F29: 30-CORDANTA | G29: 023 | H29: 1C 12M | I29: Colheita Encerrada | J29: MOAGEM | K29: 22/05/2026 | L29: 5.95 | M29: 5.95 | N29: 5.95 | O29: 100 | P29: 714 | Q29: 1042.76 | R29: -328.76 | S29: 120 | T29: 175.25 | U29: 46.04 | V29: Pedro Canario
A30: 2026/2027 | B30: 2026/2027 | C30: ACIONISTA | D30: 8664 | E30: FAZ. CORDANTA A_ Nerzy | F30: 30-CORDANTA | G30: 024 | H30: 1C 12M | I30: Colheita Encerrada | J30: MOAGEM | K30: 22/05/2026 | L30: 4.27 | M30: 4.27 | N30: 4.27 | O30: 100 | P30: 512.4 | Q30: 748.303 | R30: -235.903 | S30: 120 | T30: 175.25 | U30: 46.04 | V30: Nanuque
A31: 2026/2027 | B31: 2026/2027 | C31: ACIONISTA | D31: 8664 | E31: FAZ. CORDANTA A_ Nerzy | F31: 30-CORDANTA | G31: 026 | H31: 1C 12M | I31: Colheita Encerrada | J31: MOAGEM | K31: 22/05/2026 | L31: 1.16 | M31: 1.16 | N31: 1.16 | O31: 100 | P31: 139.2 | Q31: 203.292 | R31: -64.092 | S31: 120 | T31: 175.25 | U31: 46.04 | V31: São Mateus
A32: 2026/2027 | B32: 2026/2027 | C32: ACIONISTA | D32: 8664 | E32: FAZ. CORDANTA A_ Nerzy | F32: 30-CORDANTA | G32: 027 | H32: 1C 12M | I32: Colheita Encerrada | J32: MOAGEM | K32: 22/05/2026 | L32: 9.61 | M32: 9.61 | N32: 9.61 | O32: 100 | P32: 1153.2 | Q32: 1684.119 | R32: -530.919 | S32: 120 | T32: 175.25 | U32: 46.04 | V32: Pinheiros
A33: 2026/2027 | B33: 2026/2027 | C33: ACIONISTA | D33: 8664 | E33: FAZ. CORDANTA A_ Nerzy | F33: 30-CORDANTA | G33: 028 | H33: 1C 12M | I33: Colheita Encerrada | J33: MOAGEM | K33: 22/05/2026 | L33: 1.59 | M33: 1.59 | N33: 1.59 | O33: 100 | P33: 190.8 | Q33: 278.66 | R33: -87.86 | S33: 120 | T33: 175.26 | U33: 46.05 | V33: Boa Esperaça
A34: 2026/2027 | B34: 2026/2027 | C34: ACIONISTA | D34: 8664 | E34: FAZ. CORDANTA A_ Nerzy | F34: 30-CORDANTA | G34: 029 | H34: 1C 12M | I34: Colheita Encerrada | J34: MOAGEM | K34: 22/05/2026 | L34: 0.42 | M34: 0.42 | N34: 0.42 | O34: 100 | P34: 50.4 | Q34: 73.591 | R34: -23.191 | S34: 120 | T34: 175.22 | U34: 46.01 | V34: Mucuri
A35: 2026/2027 | B35: 2026/2027 | C35: ACIONISTA | D35: 8664 | E35: FAZ. CORDANTA A_ Nerzy | F35: 30-CORDANTA | G35: 030 | H35: 1C 12M | I35: Colheita Encerrada | J35: MOAGEM | K35: 22/05/2026 | L35: 15.46 | M35: 15.46 | N35: 15.46 | O35: 100 | P35: 1855.2 | Q35: 2709.347 | R35: -854.147 | S35: 120 | T35: 175.25 | U35: 46.04 | V35: Motanha
A36: 2026/2027 | B36: 2026/2027 | C36: ACIONISTA | D36: 8664 | E36: FAZ. CORDANTA A_ Nerzy | F36: 30-CORDANTA | G36: 031 | H36: 1C 12M | I36: Colheita Encerrada | J36: MOAGEM | K36: 22/05/2026 | L36: 14.1 | M36: 14.1 | N36: 14.1 | O36: 100 | P36: 1692 | Q36: 2471.096 | R36: -779.096 | S36: 120 | T36: 175.26 | U36: 46.05 | V36: Conceição da Barra
A37: 2026/2027 | B37: 2026/2027 | C37: ACIONISTA | D37: 8664 | E37: FAZ. CORDANTA A_ Nerzy | F37: 30-CORDANTA | G37: 032 | H37: 1C 12M | I37: Colheita Encerrada | J37: MOAGEM | K37: 22/05/2026 | L37: 13.93 | M37: 13.93 | N37: 13.93 | O37: 100 | P37: 1671.6 | Q37: 2441.223 | R37: -769.623 | S37: 120 | T37: 175.25 | U37: 46.04 | V37: Braço do Rio
A38: 2026/2027 | B38: 2026/2027 | C38: ACIONISTA | D38: 1741 | E38: FAZ. CORREGO SANTO ANTONIO_ Progresso | F38: 13-PROGRESSO | G38: 002 | H38: 1C 12M | I38: Colheita Encerrada | J38: MOAGEM | K38: 24/05/2026 | L38: 8.76 | M38: 8.76 | N38: 8.76 | O38: 100 | P38: 700.8 | Q38: 975.204 | R38: -274.404 | S38: 80 | T38: 111.32 | U38: 39.16 | V38: Pedro Canario
... A44: 2026/2027 | B44: 2026/2027 | C44: ACIONISTA | D44: 9035 | E44: FAZ. FRENTE DA LACUNA_ Nerzy | F44: 24-TAQUARA | G44: 009 | H44: 1C 12M | I44: Colheita Encerrada | J44: MOAGEM | K44: 26/05/2026 | L44: 11.9 | M44: 11.9 | N44: 11.9 | O44: 100 | P44: 1547 | Q44: 1765.865 | R44: -218.865 | S44: 130 | T44: 148.39 | U44: 14.15 | V44: Motanha
A45: 2026/2027 | B45: 2026/2027 | C45: ACIONISTA | D45: 9035 | E45: FAZ. FRENTE DA LACUNA_ Nerzy | F45: 24-TAQUARA | G45: 010 | H45: 1C 12M | I45: Colheita Encerrada | J45: MOAGEM | K45: 26/05/2026 | L45: 11.06 | M45: 11.06 | N45: 11.06 | O45: 100 | P45: 1437.8 | Q45: 1641.218 | R45: -203.418 | S45: 130 | T45: 148.39 | U45: 14.15
A46: 2026/2027 | B46: 2026/2027 | C46: ACIONISTA | D46: 9035 | E46: FAZ. FRENTE DA LACUNA_ Nerzy | F46: 24-TAQUARA | G46: 011 | H46: 1C 12M | I46: Colheita Encerrada | J46: MOAGEM | K46: 26/05/2026 | L46: 10.99 | M46: 10.99 | N46: 10.99 | O46: 100 | P46: 1428.7 | Q46: 1630.834 | R46: -202.134 | S46: 130 | T46: 148.39 | U46: 14.15
A47: 2026/2027 | B47: 2026/2027 | C47: ACIONISTA | D47: 9035 | E47: FAZ. FRENTE DA LACUNA_ Nerzy | F47: 24-TAQUARA | G47: 012 | H47: 1C 12M | I47: Colheita Encerrada | J47: MOAGEM | K47: 26/05/2026 | L47: 1.47 | M47: 1.47 | N47: 1.47 | O47: 100 | P47: 191.1 | Q47: 218.148 | R47: -27.048 | S47: 130 | T47: 148.4 | U47: 14.15
A48: 2026/2027 | B48: 2026/2027 | C48: ACIONISTA | D48: 9035 | E48: FAZ. FRENTE DA LACUNA_ Nerzy | F48: 24-TAQUARA | G48: 013 | H48: 1C 12M | I48: Colheita Encerrada | J48: MOAGEM | K48: 26/05/2026 | L48: 12.01 | M48: 12.01 | N48: 12.01 | O48: 100 | P48: 1561.3 | Q48: 1782.214 | R48: -220.914 | S48: 130 | T48: 148.39 | U48: 14.15
A49: 2026/2027 | B49: 2026/2027 | C49: ACIONISTA | D49: 9035 | E49: FAZ. FRENTE DA LACUNA_ Nerzy | F49: 24-TAQUARA | G49: 014 | H49: 1C 12M | I49: Colheita Encerrada | J49: MOAGEM | K49: 26/05/2026 | L49: 11.8 | M49: 11.8 | N49: 11.8 | O49: 100 | P49: 1534 | Q49: 1751.023 | R49: -217.023 | S49: 130 | T49: 148.39 | U49: 14.15
A50: 2026/2027 | B50: 2026/2027 | C50: ACIONISTA | D50: 9636 | E50: FAZ. CAMPO VERDE_Nerzy_Kelly | F50: 24-TAQUARA | G50: 005 | H50: 1C 12M | I50: Colheita Encerrada | J50: MOAGEM | K50: 02/06/2026 | L50: 5.38 | M50: 5.38 | N50: 5.38 | O50: 100 | P50: 484.2 | Q50: 628.807 | R50: -144.607 | S50: 90 | T50: 116.88 | U50: 29.87
...

Sheet BASEATR
A1: Unidade Receptora | B1: Projeto | C1: Periodo | D1: Fundo Agrícola | E1: Data Produção | F1: Qtd Cargas | G1: Qtd Analises | H1: Produção Total | I1: Produção Analisada | J1: BRIX | K1: LS | L1: PBU | M1: PH | N1: Impureza Mineral | O1: ATR | P1: Fibra | Q1: AR Caldo | R1: AR Cana | S1: POL Caldo | T1: POL Cana | U1: Pureza
A2: NDB HOLDING AGRICOLA LTDA | B2: 2026/2027 | C2: 2026/2027 | D2: 167 - FAZ. SAYONARA - PROJETO 16 | E2: 17/04/2026 | F2: 44 | G2: 13 | H2: 1293.26 | I2: 382.04 | J2: 13.75 | K2: 41.44 | L2: 161.52 | M2: 4.96 | N2: 0 | O2: 89.05 | P2: 13.8 | Q2: 1.09 | R2: 0.89 | S2: 10.23 | T2: 8.4 | U2: 74.41
A3: NDB HOLDING AGRICOLA LTDA | B3: 2026/2027 | C3: 2026/2027 | D3: 205 - FAZ. SAYONARA - PROJETO 22 | E3: 17/04/2026 | F3: 11 | G3: 6 | H3: 324.46 | I3: 169.48 | J3: 14.87 | K3: 46.18 | L3: 161.84 | M3: 5.23 | N3: 0 | O3: 97.35 | P3: 13.82 | Q3: 1.02 | R3: 0.84 | S3: 11.35 | T3: 9.31 | U3: 76.34
A4: NDB HOLDING AGRICOLA LTDA | B4: 2026/2027 | C4: 2026/2027 | D4: 5941 - FAZ. YPUEIRÁ_ Erivan | E4: 17/04/2026 | F4: 18 | G4: 9 | H4: 520.86 | I4: 260.99 | J4: 16.01 | K4: 50.62 | L4: 160.14 | M4: 4.38 | N4: 0 | O4: 105.51 | P4: 13.69 | Q4: 0.99 | R4: 0.81 | S4: 12.39 | T4: 10.18 | U4: 77.36
A5: NDB HOLDING AGRICOLA LTDA | B5: 2026/2027 | C5: 2026/2027 | D5: 7391 - FAZ. SANTA HELENA II_ Diomedes Picolli | E5: 17/04/2026 | F5: 26 | G5: 14 | H5: 801.82 | I5: 434.99 | J5: 17.2 | K5: 55.55 | L5: 176.82 | M5: 4.35 | N5: 0 | O5: 111.55 | P5: 15.02 | Q5: 0.94 | R5: 0.76 | S5: 13.53 | T5: 10.86 | U5: 78.64
A6: NDB HOLDING AGRICOLA LTDA | B6: 2026/2027 | C6: 2026/2027 | D6: 8656 - FAZ. CORDANTA C_Nerzy | E6: 17/04/2026 | F6: 14 | G6: 4 | H6: 470.72 | I6: 133.45 | J6: 16.2 | K6: 53.64 | L6: 158.9 | M6: 5.23 | N6: 0 | O6: 110.55 | P6: 13.59 | Q6: 0.86 | R6: 0.71 | S6: 13.11 | T6: 10.8 | U6: 80.95
A7: NDB HOLDING AGRICOLA LTDA | B7: 2026/2027 | C7: 2026/2027 | D7: 8681 - FAZ. CANA LONGA_ Nerzy | E7: 17/04/2026 | F7: 37 | G7: 15 | H7: 1184.46 | I7: 478.81 | J7: 15.45 | K7: 46.84 | L7: 167.77 | M7: 4.21 | N7: 0 | O7: 98.11 | P7: 14.3 | Q7: 1.09 | R7: 0.89 | S7: 11.49 | T7: 9.34 | U7: 74.35
A8: NDB HOLDING AGRICOLA LTDA | B8: 2026/2027 | C8: 2026/2027 | D8: 9121 - FAZ. GUANABARA I_ Albesa | E8: 17/04/2026 | F8: 22 | G8: 6 | H8: 661.04 | I8: 188.8 | J8: 19.12 | K8: 65.85 | L8: 165.4 | M8: 4.67 | N8: 0 | O8: 130.94 | P8: 14.11 | Q8: 0.79 | R8: 0.64 | S8: 15.91 | T8: 12.98 | U8: 83.21
A9: NDB HOLDING AGRICOLA LTDA | B9: 2026/2027 | C9: 2026/2027 | D9: 9929 - FAZ. SAO PEDRO_ Alessandra Saude | E9: 17/04/2026 | F9: 4 | G9: 4 | H9: 133.8 | I9: 133.8 | J9: 15.9 | K9: 51 | L9: 151.66 | M9: 4.71 | N9: 0 | O9: 107.27 | P9: 13.01 | Q9: 0.95 | R9: 0.79 | S9: 12.48 | T9: 10.39 | U9: 78.52
A10: NDB HOLDING AGRICOLA LTDA | B10: 2026/2027 | C10: 2026/2027 | D10: 167 - FAZ. SAYONARA - PROJETO 16 | E10: 18/04/2026 | F10: 69 | G10: 17 | H10: 2029.5 | I10: 457.55 | J10: 14.42 | K10: 44.61 | L10: 169.07 | M10: 5.28 | N10: 8.87 | O10: 93.54 | P10: 14.4 | Q10: 1.03 | R10: 0.83 | S10: 10.99 | T10: 8.92 | U10: 76.18
A11: NDB HOLDING AGRICOLA LTDA | B11: 2026/2027 | C11: 2026/2027 | D11: 205 - FAZ. SAYONARA - PROJETO 22 | E11: 18/04/2026 | F11: 20 | G11: 6 | H11: 556.08 | I11: 163.68 | J11: 14.96 | K11: 46.55 | L11: 176.11 | M11: 5.33 | N11: 0 | O11: 96.04 | P11: 14.96 | Q11: 1.02 | R11: 0.82 | S11: 11.44 | T11: 9.19 | U11: 76.46
A12: NDB HOLDING AGRICOLA LTDA | B12: 2026/2027 | C12: 2026/2027 | D12: 5941 - FAZ. YPUEIRÁ_ Erivan | E12: 18/04/2026 | F12: 24 | G12: 11 | H12: 728.74 | I12: 325.96 | J12: 16.27 | K12: 52.97 | L12: 156.81 | M12: 4.83 | N12: 15.13 | O12: 109.9 | P12: 13.42 | Q12: 0.91 | R12: 0.75 | S12: 12.95 | T12: 10.7 | U12: 79.58
A13: NDB HOLDING AGRICOLA LTDA | B13: 2026/2027 | C13: 2026/2027 | D13: 7391 - FAZ. SANTA HELENA II_ Diomedes Picolli | E13: 18/04/2026 | F13: 50 | G13: 13 | H13: 1557.16 | I13: 408.62 | J13: 17.17 | K13: 56.93 | L13: 166.9 | M13: 4.64 | N13: 0 | O13: 115.24 | P13: 14.23 | Q13: 0.87 | R13: 0.71 | S13: 13.86 | T13: 11.29 | U13: 80.75
... A790: NDB HOLDING AGRICOLA LTDA | B790: 2026/2027 | C790: 2026/2027 | D790: 9974 - FAZ. SOUZA LINDA_ Nerzy | E790: 12/07/2026 | F790: 50 | G790: 15 | H790: 1474.9 | I790: 428.01 | J790: 18.25 | K790: 62.08 | L790: 174.98 | M790: 4.56 | N790: 8.67 | O790: 122.7 | P790: 14.87 | Q790: 0.81 | R790: 0.65 | S790: 15.05 | T790: 12.12 | U790: 82.48

Sheet ESTIMATIVA
A1: Safra | B1: Setor | C1: Gleba | D1: Código Fazenda | E1: Fazenda | F1: Folha | G1: Variedade | H1: Data Colheita/Plantio | I1: Área Cadastro | J1: Área Estimada | K1: TCH Estimado | L1: TCH Real | M1: Finalidade | N1: Tonelada Real | O1: cidade
A2: 2026/2027 | B2: ACIONISTA | C2: 01-PROXIMO | D2: 19 | E2: FAZ. SAYONARA - PROJETO 01 | F2: 5C | G2: RB11-7436 | H2: 14/04/2025 | I2: 25.49 | J2: 25.49 | K2: 55 | L2: 0 | M2: MOAGEM | N2: 0 | O2: Conceição da Barra
A3: 2026/2027 | B3: ACIONISTA | C3: 01-PROXIMO | D3: 19 | E3: FAZ. SAYONARA - PROJETO 01 | F3: 5C | G3: RB10-8519 | H3: 14/04/2025 | I3: 8.8 | J3: 8.8 | K3: 55 | L3: 0 | M3: MOAGEM | N3: 0 | O3: Braço do Rio
A4: 2026/2027 | B4: ACIONISTA | C4: 01-PROXIMO | D4: 27 | E4: FAZ. SAYONARA - PROJETO 02 | F4: 5C | G4: RB11-7436 | H4: 28/06/2025 | I4: 29.45 | J4: 29.45 | K4: 55 | L4: 0 | M4: MOAGEM | N4: 0 | O4: Pedro Canario
A5: 2026/2027 | B5: ACIONISTA | C5: 01-PROXIMO | D5: 35 | E5: FAZ. SAYONARA - PROJETO 03 | F5: 5C | G5: RB11-7436 | H5: 28/06/2025 | I5: 47.17 | J5: 47.17 | K5: 55 | L5: 0 | M5: MOAGEM | N5: 0 | O5: Nanuque
A6: 2026/2027 | B6: ACIONISTA | C6: 01-PROXIMO | D6: 43 | E6: FAZ. SAYONARA - PROJETO 07 | F6: 2C | G6: RB92-5345 | H6: 19/11/2025 | I6: 10.04 | J6: 4.1 | K6: 80 | L6: 0 | M6: MOAGEM | N6: 0 | O6: São Mateus
A7: 2026/2027 | B7: ACIONISTA | C7: 01-PROXIMO | D7: 43 | E7: FAZ. SAYONARA - PROJETO 07 | F7: 1C 18M | G7: CTC9001BT | H7: 03/03/2025 | I7: 8.32 | J7: 3.03 | K7: 105 | L7: 0 | M7: MOAGEM | N7: 0 | O7: Pinheiros
A8: 2026/2027 | B8: ACIONISTA | C8: 01-PROXIMO | D8: 43 | E8: FAZ. SAYONARA - PROJETO 07 | F8: 1C 18M | G8: RB92-5345 | H8: 03/03/2025 | I8: 8.79 | J8: 5 | K8: 105 | L8: 0 | M8: MOAGEM | N8: 0 | O8: Boa Esperaça
A9: 2026/2027 | B9: ACIONISTA | C9: 01-PROXIMO | D9: 43 | E9: FAZ. SAYONARA - PROJETO 07 | F9: 2C | G9: RB20-8504 | H9: 19/11/2025 | I9: 10.04 | J9: 0.34 | K9: 80 | L9: 0 | M9: MOAGEM | N9: 0 | O9: Mucuri
A10: 2026/2027 | B10: ACIONISTA | C10: 01-PROXIMO | D10: 43 | E10: FAZ. SAYONARA - PROJETO 07 | F10: 1C 18M | G10: CTNE0787 | H10: 03/03/2025 | I10: 6.3 | J10: 3.95 | K10: 105 | L10: 0 | M10: MOAGEM | N10: 0 | O10: Motanha
A11: 2026/2027 | B11: ACIONISTA | C11: 01-PROXIMO | D11: 43 | E11: FAZ. SAYONARA - PROJETO 07 | F11: 2C | G11: RB16-8058 | H11: 19/11/2025 | I11: 10.04 | J11: 2.6 | K11: 80 | L11: 0 | M11: MOAGEM | N11: 0 | O11: Conceição da Barra
A12: 2026/2027 | B12: ACIONISTA | C12: 01-PROXIMO | D12: 43 | E12: FAZ. SAYONARA - PROJETO 07 | F12: 2C | G12: RB00-6995 | H12: 19/11/2025 | I12: 10.04 | J12: 3 | K12: 80 | L12: 0 | M12: MOAGEM | N12: 0 | O12: Braço do Rio
A13: 2026/2027 | B13: ACIONISTA | C13: 01-PROXIMO | D13: 43 | E13: FAZ. SAYONARA - PROJETO 07 | F13: 1C 18M | G13: RB00-6995 | H13: 03/03/2025 | I13: 23.41 | J13: 11.43 | K13: 105 | L13: 0 | M13: MOAGEM | N13: 0 | O13: Pedro Canario
... A19: 2026/2027 | B19: ACIONISTA | C19: 01-PROXIMO | D19: 94 | E19: FAZ. SAYONARA - PROJETO 06 | F19: 5C | G19: RB97-5952 | H19: 24/06/2025 | I19: 4.81 | J19: 4.81 | K19: 55 | L19: 0 | M19: MOAGEM | N19: 0 | O19: Motanha
A20: 2026/2027 | B20: ACIONISTA | C20: 01-PROXIMO | D20: 94 | E20: FAZ. SAYONARA - PROJETO 06 | F20: 5C | G20: RB97-5033 | H20: 24/06/2025 | I20: 7.39 | J20: 7.39 | K20: 55 | L20: 0 | M20: MOAGEM | N20: 0
A21: 2026/2027 | B21: ACIONISTA | C21: 01-PROXIMO | D21: 94 | E21: FAZ. SAYONARA - PROJETO 06 | F21: 4C | G21: RB97-5952 | H21: 06/08/2025 | I21: 8.9 | J21: 8.9 | K21: 60 | L21: 0 | M21: MOAGEM | N21: 0
A22: 2026/2027 | B22: ACIONISTA | C22: 01-PROXIMO | D22: 108 | E22: FAZ. SAYONARA - PROJETO 10 | F22: 10C | G22: RB95-5977 | H22: 01/01/2026 | I22: 6.42 | J22: 6.42 | K22: 50 | L22: 0 | M22: MOAGEM | N22: 0
A23: 2026/2027 | B23: ACIONISTA | C23: 01-PROXIMO | D23: 108 | E23: FAZ. SAYONARA - PROJETO 10 | F23: 4C | G23: VIVEIRO | H23: 01/01/2026 | I23: 9.05 | J23: 9.05 | K23: 60 | L23: 0 | M23: MOAGEM | N23: 0
A24: 2026/2027 | B24: ACIONISTA | C24: 01-PROXIMO | D24: 108 | E24: FAZ. SAYONARA - PROJETO 10 | F24: 5C | G24: RB95-5977 | H24: 01/01/2026 | I24: 3.43 | J24: 3.43 | K24: 55 | L24: 0 | M24: MOAGEM | N24: 0
A25: 2026/2027 | B25: ACIONISTA | C25: 01-PROXIMO | D25: 108 | E25: FAZ. SAYONARA - PROJETO 10 | F25: 5C | G25: RB86-7515 | H25: 01/01/2026 | I25: 7.81 | J25: 7.81 | K25: 55 | L25: 0 | M25: MOAGEM | N25: 0
A26: 2026/2027 | B26: ACIONISTA | C26: 01-PROXIMO | D26: 108 | E26: FAZ. SAYONARA - PROJETO 10 | F26: 9C | G26: RB95-5977 | H26: 01/01/2026 | I26: 107.54 | J26: 107.54 | K26: 50 | L26: 0 | M26: MOAGEM | N26: 0
A27: 2026/2027 | B27: ACIONISTA | C27: 01-PROXIMO | D27: 116 | E27: FAZ. SAYONARA - PROJETO 11 | F27: 3C | G27: RB01-1443 | H27: 03/01/2025 | I27: 1.32 | J27: 0.32 | K27: 110 | L27: 138.49 | M27: MOAGEM | N27: 182.81 | O27: Conceição da Barra
A28: 2026/2027 | B28: ACIONISTA | C28: 01-PROXIMO | D28: 116 | E28: FAZ. SAYONARA - PROJETO 11 | F28: 3C | G28: RB00-6995 | H28: 10/12/2025 | I28: 106.87 | J28: 106.55 | K28: 110 | L28: 138.51 | M28: MOAGEM | N28: 14802.13 | O28: Braço do Rio
A29: 2026/2027 | B29: ACIONISTA | C29: 01-PROXIMO | D29: 124 | E29: FAZ. SAYONARA - PROJETO 12 | F29: 8C | G29: RB86-7515 | H29: 13/04/2025 | I29: 2.41 | J29: 2.41 | K29: 50 | L29: 81.13 | M29: MOAGEM | N29: 195.52 | O29: Pedro Canario
A30: 2026/2027 | B30: ACIONISTA | C30: 01-PROXIMO | D30: 124 | E30: FAZ. SAYONARA - PROJETO 12 | F30: 7C | G30: RB93-7570 | H30: 15/09/2023 | I30: 4.54 | J30: 4.54 | K30: 50 | L30: 81.13 | M30: MOAGEM | N30: 368.33 | O30: Nanuque
A31: 2026/2027 | B31: ACIONISTA | C31: 01-PROXIMO | D31: 124 | E31: FAZ. SAYONARA - PROJETO 12 | F31: 6C | G31: RB86-7515 | H31: 13/04/2025 | I31: 50.92 | J31: 50.92 | K31: 50 | L31: 60.38 | M31: MOAGEM | N31: 3074.8 | O31: São Mateus
A32: 2026/2027 | B32: ACIONISTA | C32: 01-PROXIMO | D32: 132 | E32: FAZ. SAYONARA - PROJETO 13 | F32: 1C 12M | G32: RB 056251 | H32: 02/01/2024 | I32: 2.9 | J32: 0.7 | K32: 90 | L32: 0 | M32: MOAGEM | N32: 0 | O32: Pinheiros
A33: 2026/2027 | B33: ACIONISTA | C33: 01-PROXIMO | D33: 132 | E33: FAZ. SAYONARA - PROJETO 13 | F33: 1C 12M | G33: VIVEIRO | H33: 02/01/2024 | I33: 2.9 | J33: 1.5 | K33: 90 | L33: 0 | M33: MOAGEM | N33: 0 | O33: Boa Esperaça
A34: 2026/2027 | B34: ACIONISTA | C34: 01-PROXIMO | D34: 132 | E34: FAZ. SAYONARA - PROJETO 13 | F34: 1C 18M | G34: VIVEIRO | H34: 20/03/2025 | I34: 3 | J34: 3 | K34: 105 | L34: 0 | M34: MOAGEM | N34: 0 | O34: Mucuri
